{"trial_id": "1", "hyperparameters": {"space": [{"class_name": "Int", "config": {"name": "input_unit", "default": null, "conditions": [], "min_value": 32, "max_value": 512, "step": 32, "sampling": "linear"}}, {"class_name": "Int", "config": {"name": "n_layers", "default": null, "conditions": [], "min_value": 1, "max_value": 4, "step": 1, "sampling": "linear"}}, {"class_name": "Int", "config": {"name": "lstm_0_units", "default": null, "conditions": [], "min_value": 32, "max_value": 512, "step": 32, "sampling": "linear"}}, {"class_name": "Int", "config": {"name": "layer_2_neurons", "default": null, "conditions": [], "min_value": 32, "max_value": 512, "step": 32, "sampling": "linear"}}, {"class_name": "Float", "config": {"name": "Dropout_rate", "default": 0.0, "conditions": [], "min_value": 0.0, "max_value": 0.5, "step": 0.1, "sampling": "linear"}}], "values": {"input_unit": 32, "n_layers": 1, "lstm_0_units": 32, "layer_2_neurons": 32, "Dropout_rate": 0.1}}, "metrics": {"metrics": {}}, "score": null, "best_step": 0, "status": "FAILED", "message": "Traceback (most recent call last):\n  File \"c:\\Users\\natkn\\anaconda3\\envs\\gpt-twitter\\lib\\site-packages\\keras_tuner\\src\\engine\\base_tuner.py\", line 274, in _try_run_and_update_trial\n    self._run_and_update_trial(trial, *fit_args, **fit_kwargs)\n  File \"c:\\Users\\natkn\\anaconda3\\envs\\gpt-twitter\\lib\\site-packages\\keras_tuner\\src\\engine\\base_tuner.py\", line 239, in _run_and_update_trial\n    results = self.run_trial(trial, *fit_args, **fit_kwargs)\n  File \"c:\\Users\\natkn\\anaconda3\\envs\\gpt-twitter\\lib\\site-packages\\keras_tuner\\src\\engine\\tuner.py\", line 314, in run_trial\n    obj_value = self._build_and_fit_model(trial, *args, **copied_kwargs)\n  File \"c:\\Users\\natkn\\anaconda3\\envs\\gpt-twitter\\lib\\site-packages\\keras_tuner\\src\\engine\\tuner.py\", line 233, in _build_and_fit_model\n    results = self.hypermodel.fit(hp, model, *args, **kwargs)\n  File \"c:\\Users\\natkn\\anaconda3\\envs\\gpt-twitter\\lib\\site-packages\\keras_tuner\\src\\engine\\hypermodel.py\", line 149, in fit\n    return model.fit(*args, **kwargs)\n  File \"c:\\Users\\natkn\\anaconda3\\envs\\gpt-twitter\\lib\\site-packages\\keras\\src\\utils\\traceback_utils.py\", line 70, in error_handler\n    raise e.with_traceback(filtered_tb) from None\n  File \"C:\\Users\\natkn\\AppData\\Local\\Temp\\__autograph_generated_fileuiam9_z2.py\", line 15, in tf__train_function\n    retval_ = ag__.converted_call(ag__.ld(step_function), (ag__.ld(self), ag__.ld(iterator)), None, fscope)\nTypeError: in user code:\n\n    File \"c:\\Users\\natkn\\anaconda3\\envs\\gpt-twitter\\lib\\site-packages\\keras\\src\\engine\\training.py\", line 1338, in train_function  *\n        return step_function(self, iterator)\n    File \"c:\\Users\\natkn\\anaconda3\\envs\\gpt-twitter\\lib\\site-packages\\keras\\src\\engine\\training.py\", line 1322, in step_function  **\n        outputs = model.distribute_strategy.run(run_step, args=(data,))\n    File \"c:\\Users\\natkn\\anaconda3\\envs\\gpt-twitter\\lib\\site-packages\\keras\\src\\engine\\training.py\", line 1303, in run_step  **\n        outputs = model.train_step(data)\n    File \"c:\\Users\\natkn\\anaconda3\\envs\\gpt-twitter\\lib\\site-packages\\keras\\src\\engine\\training.py\", line 1085, in train_step\n        return self.compute_metrics(x, y, y_pred, sample_weight)\n    File \"c:\\Users\\natkn\\anaconda3\\envs\\gpt-twitter\\lib\\site-packages\\keras\\src\\engine\\training.py\", line 1179, in compute_metrics\n        self.compiled_metrics.update_state(y, y_pred, sample_weight)\n    File \"c:\\Users\\natkn\\anaconda3\\envs\\gpt-twitter\\lib\\site-packages\\keras\\src\\engine\\compile_utils.py\", line 605, in update_state\n        metric_obj.update_state(y_t, y_p, sample_weight=mask)\n    File \"c:\\Users\\natkn\\anaconda3\\envs\\gpt-twitter\\lib\\site-packages\\keras\\src\\utils\\metrics_utils.py\", line 77, in decorated\n        update_op = update_state_fn(*args, **kwargs)\n    File \"c:\\Users\\natkn\\anaconda3\\envs\\gpt-twitter\\lib\\site-packages\\keras\\src\\metrics\\base_metric.py\", line 140, in update_state_fn\n        return ag_update_state(*args, **kwargs)\n    File \"c:\\Users\\natkn\\anaconda3\\envs\\gpt-twitter\\lib\\site-packages\\keras\\src\\metrics\\base_metric.py\", line 723, in update_state  **\n        matches = ag_fn(y_true, y_pred, **self._fn_kwargs)\n\n    TypeError: 'str' object is not callable\n\n"}